Workbook

Sheet Feuil1
A1: ID | B1: Massar | C1: Nom | D1: Prenom | E1: Telephone_Pere | F1: Telephone_mere | G1: Telephone_autre | H1: Classe | I1: niveau | J1: Genre | K1: ok
A2: 1 | B2: A168048298 | C2: القندوسي | D2: حمزة | E2: 212661128085 | F2: 212671364083 | H2: TCSF-3 | I2: الجذع المشترك العلمي – خيار فرنسية | J2: ذكر | K2: =VLOOKUP(B2,Feuil2!B:B,1,0) -> A168048298
A3: 11 | B3: B160005970 | C3: ميحيت | D3: خيرة | E3: 212670206873 | F3: 212712950675 | H3: TCSF-3 | I3: الجذع المشترك العلمي – خيار فرنسية | J3: أنثى | K3: =VLOOKUP(B3,Feuil2!B:B,1,0) -> B160005970
A4: 17 | B4: B160006503 | C4: حسايني | D4: اسلام | E4: 212662819288 | H4: TCSF-3 | I4: الجذع المشترك العلمي – خيار فرنسية | J4: أنثى | K4: =VLOOKUP(B4,Feuil2!B:B,1,0) -> B160006503
A5: 12 | B5: B160025216 | C5: علاوي | D5: خولة | E5: 212666148168 | H5: TCSF-2 | I5: الجذع المشترك العلمي – خيار فرنسية | J5: أنثى | K5: =VLOOKUP(B5,Feuil2!B:B,1,0) -> B160025216
A6: 20 | B6: B160039442 | C6: الجلد | D6: آدم | E6: 212667294555 | H6: TCSF-1 | I6: الجذع المشترك العلمي – خيار فرنسية | J6: ذكر | K6: =VLOOKUP(B6,Feuil2!B:B,1,0) -> B160039442
A7: 20 | B7: B160039442 | C7: الجلد | D7: آدم | E7: 212667294555 | H7: TCSF-1 | I7: الجذع المشترك العلمي – خيار فرنسية | J7: ذكر | K7: =VLOOKUP(B7,Feuil2!B:B,1,0) -> B160039442
A8: 2 | B8: B160042328 | C8: دوحي | D8: هاجر | E8: 212661260203 | F8: 212658641474 | H8: 3APIC-1 | I8: الثالثة إعدادي مسار دولي | J8: أنثى | K8: =VLOOKUP(B8,Feuil2!B:B,1,0) -> B160042328
A9: 1 | B9: B160046082 | C9: حناني | D9: محمد أيمن | E9: 212661177772 | F9: 212645964156 | H9: TCSF-1 | I9: الجذع المشترك العلمي – خيار فرنسية | J9: ذكر | K9: =VLOOKUP(B9,Feuil2!B:B,1,0) -> B160046082
A10: 1 | B10: B160046082 | C10: حناني | D10: محمد أيمن | E10: 212661177772 | F10: 212645964156 | H10: TCSF-1 | I10: الجذع المشترك العلمي – خيار فرنسية | J10: ذكر | K10: =VLOOKUP(B10,Feuil2!B:B,1,0) -> B160046082
A11: 22 | B11: B160046699 | C11: العياشي | D11: نبيل | E11: 212661175654 | F11: 212661265770 | H11: TCSF-3 | I11: الجذع المشترك العلمي – خيار فرنسية | J11: ذكر | K11: =VLOOKUP(B11,Feuil2!B:B,1,0) -> B160046699
A12: 2 | B12: B161004436 | C12: دوحي | D12: هناء | E12: 212668579733 | H12: TCSF-1 | I12: الجذع المشترك العلمي – خيار فرنسية | J12: أنثى | K12: =VLOOKUP(B12,Feuil2!B:B,1,0) -> B161004436
A13: 2 | B13: B161004436 | C13: دوحي | D13: هناء | E13: 212668579733 | H13: TCSF-1 | I13: الجذع المشترك العلمي – خيار فرنسية | J13: أنثى | K13: =VLOOKUP(B13,Feuil2!B:B,1,0) -> B161004436
A14: 14 | B14: B161004447 | C14: مغفور | D14: عثمان | E14: 212661087257 | F14: 212670434903 | H14: 3APIC-3 | I14: الثالثة إعدادي مسار دولي | J14: ذكر | K14: =VLOOKUP(B14,Feuil2!B:B,1,0) -> B161004447
A15: 1 | B15: B161006718 | C15: اصغيري | D15: صفاء | E15: 212662107262 | H15: TCSF-2 | I15: الجذع المشترك العلمي – خيار فرنسية | J15: أنثى | K15: =VLOOKUP(B15,Feuil2!B:B,1,0) -> B161006718
A16: 21 | B16: B161030628 | C16: بوسغان | D16: مهدي | E16: 212668400186 | F16: 212613526158 | H16: TCSF-1 | I16: الجذع المشترك العلمي – خيار فرنسية | J16: ذكر | K16: =VLOOKUP(B16,Feuil2!B:B,1,0) -> B161030628
A17: 21 | B17: B161030628 | C17: بوسغان | D17: مهدي | E17: 212668400186 | F17: 212613526158 | H17: TCSF-1 | I17: الجذع المشترك العلمي – خيار فرنسية | J17: ذكر | K17: =VLOOKUP(B17,Feuil2!B:B,1,0) -> B161030628
A18: 3 | B18: B161035053 | C18: ركبي | D18: عثمان | E18: 212613588248 | F18: 212766935587 | H18: TCSF-1 | I18: الجذع المشترك العلمي – خيار فرنسية | J18: ذكر | K18: =VLOOKUP(B18,Feuil2!B:B,1,0) -> B161035053
A19: 3 | B19: B161035053 | C19: ركبي | D19: عثمان | E19: 212613588248 | F19: 212766935587 | H19: TCSF-1 | I19: الجذع المشترك العلمي – خيار فرنسية | J19: ذكر | K19: =VLOOKUP(B19,Feuil2!B:B,1,0) -> B161035053
A20: 4 | B20: B161040963 | C20: نجاري | D20: رانية | E20: 212628449230 | F20: 212672615777 | H20: TCSF-1 | I20: الجذع المشترك العلمي – خيار فرنسية | J20: أنثى | K20: =VLOOKUP(B20,Feuil2!B:B,1,0) -> B161040963
A21: 4 | B21: B161040963 | C21: نجاري | D21: رانية | E21: 212628449230 | F21: 212672615777 | H21: TCSF-1 | I21: الجذع المشترك العلمي – خيار فرنسية | J21: أنثى | K21: =VLOOKUP(B21,Feuil2!B:B,1,0) -> B161040963
A22: 16 | B22: B162001166 | C22: قيسي | D22: غيثة | E22: 33 7 59 48 83 15 | F22: 212601498673 | H22: TCSF-2 | I22: الجذع المشترك العلمي – خيار فرنسية | J22: أنثى | K22: =VLOOKUP(B22,Feuil2!B:B,1,0) -> B162001166
A23: 17 | B23: B162009093 | C23: حسني | D23: فردوس | F23: 212626700427 | H23: TCSF-2 | I23: الجذع المشترك العلمي – خيار فرنسية | J23: أنثى | K23: =VLOOKUP(B23,Feuil2!B:B,1,0) -> B162009093
A24: 5 | B24: B162011475 | C24: الحجراوي | D24: آية | E24: 212655494961 | F24: 212624698755 | H24: TCSF-1 | I24: الجذع المشترك العلمي – خيار فرنسية | J24: أنثى | K24: =VLOOKUP(B24,Feuil2!B:B,1,0) -> B162011475
A25: 5 | B25: B162011475 | C25: الحجراوي | D25: آية | E25: 212655494961 | F25: 212624698755 | H25: TCSF-1 | I25: الجذع المشترك العلمي – خيار فرنسية | J25: أنثى | K25: =VLOOKUP(B25,Feuil2!B:B,1,0) -> B162011475
A26: 3 | B26: B162043701 | C26: أبغرير | D26: محمد أمين | E26: 212682603895 | F26: 212762011686 | H26: TCSF-3 | I26: الجذع المشترك العلمي – خيار فرنسية | J26: ذكر | K26: =VLOOKUP(B26,Feuil2!B:B,1,0) -> B162043701
A27: 1 | B27: B162049873 | C27: بوعبداللاوي | D27: سلمى | E27: 212651353913 | F27: 212698984941 | H27: 3APIC-3 | I27: الثالثة إعدادي مسار دولي | J27: أنثى | K27: =VLOOKUP(B27,Feuil2!B:B,1,0) -> B162049873
A28: 15 | B28: B163026464 | C28: نشاط | D28: زينب | E28: 212666617942 | F28: 212642301628 | H28: TCSF-1 | I28: الجذع المشترك العلمي – خيار فرنسية | J28: أنثى | K28: =VLOOKUP(B28,Feuil2!B:B,1,0) -> B163026464
A29: 15 | B29: B163026464 | C29: نشاط | D29: زينب | E29: 212666617942 | F29: 212642301628 | H29: TCSF-1 | I29: الجذع المشترك العلمي – خيار فرنسية | J29: أنثى | K29: =VLOOKUP(B29,Feuil2!B:B,1,0) -> B163026464
A30: 20 | B30: B163029758 | C30: دحمان | D30: يوسف شاهين | E30: 212662487637 | H30: 3APIC-3 | I30: الثالثة إعدادي مسار دولي | J30: ذكر | K30: =VLOOKUP(B30,Feuil2!B:B,1,0) -> B163029758
A31: 18 | B31: B163030944 | C31: مرزوقي | D31: زهير | F31: 34 643 37 45 89 | H31: 3APIC-3 | I31: الثالثة إعدادي مسار دولي | J31: ذكر | K31: =VLOOKUP(B31,Feuil2!B:B,1,0) -> B163030944
A32: 11 | B32: B163033705 | C32: بنرحو | D32: وهيب | E32: 212667772378 | H32: 3APIC-3 | I32: الثالثة إعدادي مسار دولي | J32: ذكر | K32: =VLOOKUP(B32,Feuil2!B:B,1,0) -> B163033705
A33: 3 | B33: B163035905 | C33: أنزار | D33: عمر | E33: 212672108857 | F33: 212616837016 | H33: TCSF-2 | I33: الجذع المشترك العلمي – خيار فرنسية | J33: ذكر | K33: =VLOOKUP(B33,Feuil2!B:B,1,0) -> B163035905
A34: 4 | B34: B163043709 | C34: برمضان | D34: وردة | F34: 212613564321 | H34: TCSF-2 | I34: الجذع المشترك العلمي – خيار فرنسية | J34: أنثى | K34: =VLOOKUP(B34,Feuil2!B:B,1,0) -> B163043709
A35: 7 | B35: B163044274 | C35: اليوسفي | D35: اشرف | F35: 212626802001 | H35: TCSF-1 | I35: الجذع المشترك العلمي – خيار فرنسية | J35: ذكر | K35: =VLOOKUP(B35,Feuil2!B:B,1,0) -> B163044274
A36: 7 | B36: B163044274 | C36: اليوسفي | D36: اشرف | F36: 212626802001 | H36: TCSF-1 | I36: الجذع المشترك العلمي – خيار فرنسية | J36: ذكر | K36: =VLOOKUP(B36,Feuil2!B:B,1,0) -> B163044274
A37: 15 | B37: B163048348 | C37: وكوتي | D37: محمد أمين | E37: 212618407618 | F37: 212611507738 | H37: 3APIC-3 | I37: الثالثة إعدادي مسار دولي | J37: ذكر | K37: =VLOOKUP(B37,Feuil2!B:B,1,0) -> B163048348
A38: 22 | B38: B164008379 | C38: العياني | D38: ياسمين | E38: 212672764772 | F38: 212624250976 | H38: TCSF-1 | I38: الجذع المشترك العلمي – خيار فرنسية | J38: أنثى | K38: =VLOOKUP(B38,Feuil2!B:B,1,0) -> B164008379
A39: 22 | B39: B164008379 | C39: العياني | D39: ياسمين | E39: 212672764772 | F39: 212624250976 | H39: TCSF-1 | I39: الجذع المشترك العلمي – خيار فرنسية | J39: أنثى | K39: =VLOOKUP(B39,Feuil2!B:B,1,0) -> B164008379
A40: 16 | B40: B164012906 | C40: بوسحابة | D40: رميساء | E40: 212625115047 | F40: 212710274126 | H40: 2APIC-2 | I40: الثانية إعدادي مسار دولي | J40: أنثى | K40: =VLOOKUP(B40,Feuil2!B:B,1,0) -> B164012906
...

Sheet Feuil2
A1: N | B1: CodeMassar | C1: Nom | D1: Prenom | E1: Genre | F1: Classe | G1: Nom complet | H1: Colonne1 | I1: Colonne2
A2: 1 | B2: A168048298 | C2: القندوسي | D2: حمزة | E2: ذكر | F2: TCSF-3 | G2: الجذع المشترك العلمي – خيار فرنسية | H2: القندوسي حمزة | I2: =VLOOKUP(TB_Eleves[[#This Row],[CodeMassar]],Feuil1!B:B,1,0) -> A168048298
A3: 11 | B3: B160005970 | C3: ميحيت | D3: خيرة | E3: أنثى | F3: TCSF-3 | G3: الجذع المشترك العلمي – خيار فرنسية | H3: ميحيت خيرة | I3: =VLOOKUP(TB_Eleves[[#This Row],[CodeMassar]],Feuil1!B:B,1,0) -> B160005970
A4: 17 | B4: B160006503 | C4: حسايني | D4: اسلام | E4: أنثى | F4: TCSF-3 | G4: الجذع المشترك العلمي – خيار فرنسية | H4: حسايني اسلام | I4: =VLOOKUP(TB_Eleves[[#This Row],[CodeMassar]],Feuil1!B:B,1,0) -> B160006503
A5: 12 | B5: B160025216 | C5: علاوي | D5: خولة | E5: أنثى | F5: TCSF-2 | G5: الجذع المشترك العلمي – خيار فرنسية | H5: علاوي خولة | I5: =VLOOKUP(TB_Eleves[[#This Row],[CodeMassar]],Feuil1!B:B,1,0) -> B160025216
A6: 20 | B6: B160039442 | C6: الجلد | D6: آدم | E6: ذكر | F6: TCSF-1 | G6: الجذع المشترك العلمي – خيار فرنسية | H6: الجلد آدم | I6: =VLOOKUP(TB_Eleves[[#This Row],[CodeMassar]],Feuil1!B:B,1,0) -> B160039442
A7: 2 | B7: B160042328 | C7: دوحي | D7: هاجر | E7: أنثى | F7: 3APIC-1 | G7: الثالثة إعدادي مسار دولي | H7: دوحي هاجر | I7: =VLOOKUP(TB_Eleves[[#This Row],[CodeMassar]],Feuil1!B:B,1,0) -> B160042328
A8: 1 | B8: B160046082 | C8: حناني | D8: محمد أيمن | E8: ذكر | F8: TCSF-1 | G8: الجذع المشترك العلمي – خيار فرنسية | H8: حناني محمد أيمن | I8: =VLOOKUP(TB_Eleves[[#This Row],[CodeMassar]],Feuil1!B:B,1,0) -> B160046082
A9: 22 | B9: B160046699 | C9: العياشي | D9: نبيل | E9: ذكر | F9: TCSF-3 | G9: الجذع المشترك العلمي – خيار فرنسية | H9: العياشي نبيل | I9: =VLOOKUP(TB_Eleves[[#This Row],[CodeMassar]],Feuil1!B:B,1,0) -> B160046699
A10: 2 | B10: B161004436 | C10: دوحي | D10: هناء | E10: أنثى | F10: TCSF-1 | G10: الجذع المشترك العلمي – خيار فرنسية | H10: دوحي هناء | I10: =VLOOKUP(TB_Eleves[[#This Row],[CodeMassar]],Feuil1!B:B,1,0) -> B161004436
A11: 14 | B11: B161004447 | C11: مغفور | D11: عثمان | E11: ذكر | F11: 3APIC-3 | G11: الثالثة إعدادي مسار دولي | H11: مغفور عثمان | I11: =VLOOKUP(TB_Eleves[[#This Row],[CodeMassar]],Feuil1!B:B,1,0) -> B161004447
A12: 1 | B12: B161006718 | C12: اصغيري | D12: صفاء | E12: أنثى | F12: TCSF-2 | G12: الجذع المشترك العلمي – خيار فرنسية | H12: اصغيري صفاء | I12: =VLOOKUP(TB_Eleves[[#This Row],[CodeMassar]],Feuil1!B:B,1,0) -> B161006718
A13: 21 | B13: B161030628 | C13: بوسغان | D13: مهدي | E13: ذكر | F13: TCSF-1 | G13: الجذع المشترك العلمي – خيار فرنسية | H13: بوسغان مهدي | I13: =VLOOKUP(TB_Eleves[[#This Row],[CodeMassar]],Feuil1!B:B,1,0) -> B161030628
... A466: 20 | B466: H145082456 | C466: العامري | D466: محمد أمين | E466: ذكر | F466: 2BACSPF-4 | G466: الثانية باكالوريا العلوم الفيزيائية – خ. فرنسية | H466: العامري محمد أمين | I466: =VLOOKUP(TB_Eleves[[#This Row],[CodeMassar]],Feuil1!B:B,1,0) -> H145082456
